#VRML_SIM R2021a utf8
WorldInfo {
  basicTimeStep 16
  coordinateSystem "NUE"
  contactProperties [
    ContactProperties {
      material2 "slippy"
      coulombFriction [
        0
      ]
    }
    ContactProperties {
      material2 "block"
      coulombFriction [
        0.01
      ]
    }
  ]
}
Viewpoint {
  orientation 0.31407793722981486 0.9290934550293322 0.1952956762632562 4.44522450003701
  position -3.3090531876204716 1.782895231843818 -0.21642147298260883
}
TexturedBackground {
}
TexturedBackgroundLight {
}
Floor {
  size 2.4 2.4
  appearance Asphalt {
  }
}
DEF Block_R1 Solid {
  translation 0.377 0.05 -0.9
  children [
    DEF BOX_R Shape {
      appearance PBRAppearance {
        baseColor 1 0 0
        metalness 0
      }
      geometry Box {
        size 0.05 0.05 0.05
      }
    }
  ]
  name "solid(4)"
  contactMaterial "box"
  boundingObject USE BOX_R
  physics Physics {
  }
}
DEF Block_R2 Solid {
  translation 0.93775 0.02 -0.551959
  scale 0.822058 0.822058 0.822058
  children [
    USE BOX_R
  ]
  name "solid(13)"
  contactMaterial "block"
  boundingObject USE BOX_R
  physics Physics {
  }
}
DEF Block_R3 Solid {
  translation -1 0.05 -0.5
  children [
    USE BOX_R
  ]
  name "solid(12)"
  boundingObject USE BOX_R
  physics Physics {
  }
}
DEF Block_R4 Solid {
  translation 0.1 0.05 1.1
  children [
    USE BOX_R
  ]
  name "solid(7)"
  boundingObject USE BOX_R
  physics Physics {
  }
}
DEF Block_B1 Solid {
  translation -1.1 0.05 1
  children [
    DEF BOX_B Shape {
      appearance PBRAppearance {
        baseColor 0 0 1
        metalness 0
      }
      geometry Box {
        size 0.05 0.05 0.05
      }
    }
  ]
  name "solid(8)"
  boundingObject USE BOX_B
  physics Physics {
  }
}
DEF Block_B2 Solid {
  translation 0.03 0.05 0.72
  children [
    USE BOX_B
  ]
  name "solid(9)"
  boundingObject USE BOX_B
  physics Physics {
  }
}
DEF Block_B3 Solid {
  translation -0.85 0.05 -0.2
  children [
    USE BOX_B
  ]
  name "solid(10)"
  boundingObject USE BOX_B
  physics Physics {
  }
}
DEF Block_B4 Solid {
  translation 1 0.05 0.68
  children [
    USE BOX_B
  ]
  name "solid(11)"
  boundingObject USE BOX_B
  physics Physics {
  }
}
DEF Floor_colour Solid {
  translation 1 0.0001 1
  children [
    Shape {
      appearance PBRAppearance {
        baseColor 1 0 0
      }
      geometry Plane {
        size 0.4 0.4
      }
    }
  ]
  name "solid(6)"
}
DEF Floor_colour Solid {
  translation 0.99891 0.0001 -0.974527
  children [
    Shape {
      appearance PBRAppearance {
        baseColor 0 0 1
      }
      geometry Plane {
        size 0.4 0.4
      }
    }
  ]
  name "solid(5)"
}
DEF WALL_1 Solid {
  translation 1.2 0.05 0
  children [
    DEF WALL_SHAPE Shape {
      appearance PBRAppearance {
        baseColor 0.12549 0.368627 0.729412
        roughness 1
        metalness 0
      }
      geometry Box {
        size 0.02 0.1 2.38
      }
    }
  ]
  boundingObject USE WALL_SHAPE
}
DEF WALL_2 Solid {
  translation -1.2 0.05 0
  children [
    USE WALL_SHAPE
  ]
  name "solid(1)"
  boundingObject USE WALL_SHAPE
}
DEF WALL_3 Solid {
  translation 0 0.05 -1.2
  rotation 0 1 0 1.5708
  children [
    USE WALL_SHAPE
  ]
  name "solid(2)"
  boundingObject USE WALL_SHAPE
}
DEF WALL_4 Solid {
  translation 0 0.05 1.2
  rotation 0 1 0 1.5708
  children [
    USE WALL_SHAPE
  ]
  name "solid(3)"
  boundingObject USE WALL_SHAPE
}
DEF TEST_OBJECT Solid {
  translation -1 0.05 1
  children [
    DEF TEST Shape {
      appearance PBRAppearance {
        baseColor 0 1 0
      }
      geometry Sphere {
        radius 0.025
      }
    }
  ]
  name "testing sphere"
}
DEF BLUE_ROBOT Robot {
  translation 0.93887 0.07 -0.971848
  children [
    Camera {
      translation -0.01 0 0.12
      rotation 0 1 0 -1.5708
      width 1
      height 1
      far 0.05
    }
    Solid {
      translation 0 -0.055 0
      children [
        Shape {
          geometry DEF CASTOR_BALL Sphere {
            radius 0.01
          }
        }
      ]
      name "solid(2)"
      contactMaterial "slippy"
      boundingObject USE CASTOR_BALL
      physics Physics {
      }
    }
    DEF BODY Shape {
      appearance PBRAppearance {
        baseColor 0 0 1
        roughness 1
        metalness 0
      }
      geometry Box {
        size 0.135 0.105 0.102
      }
    }
    DEF Box2_R Solid {
      translation 0.06 -0.0199999 0.08
      rotation 1 0 0 1.5708
      children [
        Shape {
          appearance PBRAppearance {
          }
          geometry Box {
            size 0.003 0.064 0.064
          }
        }
      ]
      name "solid(4)"
      boundingObject Box {
        size 0.003 0.064 0.064
      }
    }
    DEF Box2_L Solid {
      translation -0.06 -0.0199999 0.08
      rotation 1 0 0 1.5708
      children [
        Shape {
          appearance PBRAppearance {
          }
          geometry Box {
            size 0.003 0.064 0.064
          }
        }
      ]
      name "solid(5)"
      boundingObject Box {
        size 0.003 0.064 0.064
      }
    }
    DEF Box2_T Solid {
      translation 6.40903e-14 0.0100001 0.0800001
      rotation -0.5773509358554485 0.5773489358556708 0.5773509358554485 -2.094395307179586
      children [
        HingeJoint {
          jointParameters HingeJointParameters {
          }
          device [
            DEF RM_L RotationalMotor {
            }
          ]
          endPoint Solid {
            rotation 1 0 0 0
            children [
              Solid {
                translation 0.03 0.06 -0.06
                scale 1.30689 1.30689 1.30689
                children [
                  Shape {
                    appearance PBRAppearance {
                      baseColor 0 0 0
                    }
                    geometry DEF flap Box {
                      size 0.0495 0.0495 0.001
                    }
                  }
                ]
              }
            ]
          }
        }
        HingeJoint {
          jointParameters HingeJointParameters {
          }
          device [
            DEF RM_R RotationalMotor {
            }
          ]
          endPoint Solid {
            rotation 1 0 0 0
            children [
              Solid {
                translation 0.03 0.06 0.06
                rotation -1 0 0 3.67802e-06
                scale 1.30689 1.30689 1.30689
                children [
                  Shape {
                    appearance PBRAppearance {
                      baseColor 0 0 0
                    }
                    geometry DEF flap Box {
                      size 0.0495 0.0495 0.001
                    }
                  }
                ]
              }
            ]
            name "solid(1)"
          }
        }
        Shape {
          appearance PBRAppearance {
          }
          geometry Box {
            size 0.004 0.064 0.12
          }
        }
      ]
      name "solid(6)"
      boundingObject Box {
        size 0.003 0.064 0.12
      }
    }
    DEF WHEEL1 HingeJoint {
      jointParameters HingeJointParameters {
        anchor 0.0779 -0.05 0.05
      }
      device [
        RotationalMotor {
          name "wheel1"
          maxTorque 100
        }
        PositionSensor {
        }
      ]
      endPoint Solid {
        translation 0.0778999 -0.0300339 0.0401015
        rotation 0.0019079727809748464 -0.0019079797047584805 -0.9999963596200304 4.712381666377444
        children [
          DEF WHEEL Shape {
            appearance PBRAppearance {
              baseColor 0.305882 0.898039 0.25098
              roughness 1
              metalness 0
            }
            geometry Cylinder {
              height 0.02
              radius 0.04
              subdivision 24
            }
          }
        ]
        boundingObject USE WHEEL
        physics Physics {
        }
      }
    }
    DEF WHEEL2 HingeJoint {
      jointParameters HingeJointParameters {
        anchor -0.06 0 0.05
      }
      device [
        RotationalMotor {
          name "wheel2"
          maxTorque 100
        }
      ]
      endPoint Solid {
        translation -0.0778999 -0.0300339 0.0401015
        rotation 0.0017048106017812177 -0.001704816680961621 -0.9999970936062246 4.712382400408873
        children [
          USE WHEEL
        ]
        name "solid(1)"
        boundingObject USE WHEEL
        physics Physics {
        }
      }
    }
    DistanceSensor {
      translation 0 -0.03 0.07
      rotation 0 1 0 -1.5708
      children [
        Shape {
          appearance PBRAppearance {
            baseColor 0.184 0.596 0.847
            metalness 0
          }
          geometry Box {
            size 0.01 0.01 0.01
          }
        }
      ]
      name "ds_long"
      lookupTable [
        0 0 0
        1.5 1500 0
      ]
    }
    GPS {
    }
    Emitter {
    }
    Receiver {
      channel 1
    }
    Compass {
    }
  ]
  name "blue"
  boundingObject USE BODY
  physics Physics {
    density -1
    mass 1
  }
  controller "<extern>"
}
DEF RED_ROBOT Robot {
  translation 0.950467 0.07 1.0518
  rotation 0 1 0 3.14159
  children [
    Camera {
      translation -0.01 0 0.12
      rotation 0 1 0 -1.5708
      width 1
      height 1
      far 0.05
    }
    Solid {
      translation 0 -0.055 0
      children [
        Shape {
          geometry DEF CASTOR_BALL Sphere {
            radius 0.01
          }
        }
      ]
      name "solid(2)"
      contactMaterial "slippy"
      boundingObject USE CASTOR_BALL
      physics Physics {
      }
    }
    DEF BODY Shape {
      appearance PBRAppearance {
        baseColor 1 0 0
        roughness 1
        metalness 0
      }
      geometry Box {
        size 0.135 0.105 0.102
      }
    }
    DEF Box2_R Solid {
      translation 0.06 -0.0199999 0.08
      rotation 1 0 0 1.5708
      children [
        Shape {
          appearance PBRAppearance {
          }
          geometry Box {
            size 0.003 0.064 0.064
          }
        }
      ]
      name "solid(4)"
      boundingObject Box {
        size 0.003 0.064 0.064
      }
    }
    DEF Box2_L Solid {
      translation -0.06 -0.0199999 0.08
      rotation 1 0 0 1.5708
      children [
        Shape {
          appearance PBRAppearance {
          }
          geometry Box {
            size 0.003 0.064 0.064
          }
        }
      ]
      name "solid(5)"
      boundingObject Box {
        size 0.003 0.064 0.064
      }
    }
    DEF Box2_T Solid {
      translation 6.40903e-14 0.0100001 0.0800001
      rotation 0.5773509358554486 -0.5773489358556709 -0.5773509358554486 2.094395307179586
      children [
        HingeJoint {
          jointParameters HingeJointParameters {
          }
          device [
            DEF RM_L RotationalMotor {
            }
          ]
          endPoint Solid {
            rotation 1 0 0 0
            children [
              Solid {
                translation 0.03 0.06 -0.06
                scale 1.30689 1.30689 1.30689
                children [
                  Shape {
                    appearance PBRAppearance {
                      baseColor 0 0 0
                    }
                    geometry DEF flap Box {
                      size 0.0495 0.0495 0.001
                    }
                  }
                ]
              }
            ]
          }
        }
        HingeJoint {
          jointParameters HingeJointParameters {
          }
          device [
            DEF RM_R RotationalMotor {
            }
          ]
          endPoint Solid {
            rotation 1 0 0 0
            children [
              Solid {
                translation 0.03 0.06 0.06
                rotation -1 0 0 3.67802e-06
                scale 1.30689 1.30689 1.30689
                children [
                  Shape {
                    appearance PBRAppearance {
                      baseColor 0 0 0
                    }
                    geometry DEF flap Box {
                      size 0.0495 0.0495 0.001
                    }
                  }
                ]
              }
            ]
            name "solid(1)"
          }
        }
        Shape {
          appearance PBRAppearance {
          }
          geometry Box {
            size 0.004 0.064 0.12
          }
        }
      ]
      name "solid(6)"
      boundingObject Box {
        size 0.003 0.064 0.12
      }
    }
    DEF WHEEL1 HingeJoint {
      jointParameters HingeJointParameters {
        anchor 0.0779 -0.05 0.05
      }
      device [
        RotationalMotor {
          name "wheel1"
          maxTorque 100
        }
        PositionSensor {
        }
      ]
      endPoint Solid {
        translation 0.0778999 -0.0300339 0.0401015
        rotation 0.0019079727809748464 -0.0019079797047584805 -0.9999963596200304 4.712381666377444
        children [
          DEF WHEEL Shape {
            appearance PBRAppearance {
              baseColor 0.305882 0.898039 0.25098
              roughness 1
              metalness 0
            }
            geometry Cylinder {
              height 0.02
              radius 0.04
              subdivision 24
            }
          }
        ]
        boundingObject USE WHEEL
        physics Physics {
        }
      }
    }
    DEF WHEEL2 HingeJoint {
      jointParameters HingeJointParameters {
        anchor -0.06 0 0.05
      }
      device [
        RotationalMotor {
          name "wheel2"
          maxTorque 100
        }
      ]
      endPoint Solid {
        translation -0.0778999 -0.0300339 0.0401015
        rotation 0.0017048106017812177 -0.001704816680961621 -0.9999970936062246 4.712382400408873
        children [
          USE WHEEL
        ]
        name "solid(1)"
        boundingObject USE WHEEL
        physics Physics {
        }
      }
    }
    DistanceSensor {
      translation 0 -0.03 0.07
      rotation 0 1 0 -1.5708
      children [
        Shape {
          appearance PBRAppearance {
            baseColor 0.184 0.596 0.847
            metalness 0
          }
          geometry Box {
            size 0.01 0.01 0.01
          }
        }
      ]
      name "ds_long"
      lookupTable [
        0 0 0
        1.5 1500 0
      ]
    }
    GPS {
    }
    Emitter {
    }
    Receiver {
      channel 1
    }
    Compass {
    }
  ]
  name "red"
  boundingObject USE BODY
  physics Physics {
    density -1
    mass 1
  }
  controller "<extern>"
}
